<?xml version="1.0" ?>
<sdf version="1.8">
  <world name="default">
    <gravity>0 0 -9.81</gravity>
    <physics name="1ms" type="ignored">
      <max_step_size>0.001</max_step_size>
      <real_time_factor>1.0</real_time_factor>
<!--      <real_time_update_rate>3000</real_time_update_rate>-->
    </physics>
    <plugin
            filename="gz-sim-physics-system"
            name="gz::sim::systems::Physics">
    </plugin>
    <plugin
            filename="gz-sim-user-commands-system"
            name="gz::sim::systems::UserCommands">
    </plugin>
    <plugin
            filename="gz-sim-scene-broadcaster-system"
            name="gz::sim::systems::SceneBroadcaster">
    </plugin>
    <plugin
            filename="ignition-gazebo-forcetorque-system"
            name="ignition::gazebo::systems::ForceTorque">
    </plugin>
    <plugin
            filename="gz-sim-contact-system"
            name="gz::sim::systems::Contact">
    </plugin>

    <light type="directional" name="sun">
      <cast_shadows>true</cast_shadows>
      <pose>0 0 10 0 0 0</pose>
      <diffuse>0.8 0.8 0.8 1</diffuse>
      <specular>0.2 0.2 0.2 1</specular>
      <attenuation>
        <range>1000</range>
        <constant>0.9</constant>
        <linear>0.01</linear>
        <quadratic>0.001</quadratic>
      </attenuation>
      <direction>-0.5 0.1 -0.9</direction>
    </light>

    <scene>
      <ambient>0.4 0.4 0.4 1.0</ambient>
      <background>0.7 0.7 0.7 1.0</background>
      <shadows>true</shadows>
    </scene>

    <model name="ground_plane">
      <static>true</static>
      <link name="link">
        <sensor name='ground_plane' type='contact'>
          <contact>
            <collision>collision</collision>
          </contact>
          <always_on>true</always_on>
          <update_rate>30</update_rate>
        </sensor>
        <collision name="collision">
          <geometry>
            <plane>
              <normal>0 0 1</normal>
              <size>100 100</size>
            </plane>
          </geometry>
          <surface>
            <friction>
              <ode>
                <mu>1.0</mu>
                <mu2>1.0</mu2>
              </ode>
            </friction>
            <contact>
              <ode/>
            </contact>
          </surface>
        </collision>
        <visual name="visual">
          <geometry>
            <plane>
              <normal>0 0 1</normal>
              <size>100 100</size>
            </plane>
          </geometry>
          <material>
            <ambient>0.8 0.8 0.8 1</ambient>
            <diffuse>0.8 0.8 0.8 1</diffuse>
            <specular>0 0 0 1</specular>
            <emissive>0 0 0 1</emissive>
          </material>
        </visual>
      </link>
    </model>

    <gui fullscreen="0">

      <!-- 3D scene -->
      <plugin filename="MinimalScene" name="3D View">
        <gz-gui>
          <title>3D View</title>
          <property type="bool" key="showTitleBar">false</property>
          <property type="string" key="state">docked</property>
        </gz-gui>

        <engine>ogre2</engine>
        <scene>scene</scene>
        <ambient_light>0.4 0.4 0.4</ambient_light>
        <background_color>0.8 0.8 0.8</background_color>
        <camera_pose>-6 0 6 0 0.5 0</camera_pose>
        <camera_clip>
          <near>0.25</near>
          <far>25000</far>
        </camera_clip>
      </plugin>

      <!-- Plugins that add functionality to the scene -->
      <plugin filename="EntityContextMenuPlugin" name="Entity context menu">
        <gz-gui>
          <property key="state" type="string">floating</property>
          <property key="width" type="double">5</property>
          <property key="height" type="double">5</property>
          <property key="showTitleBar" type="bool">false</property>
        </gz-gui>
      </plugin>
      <plugin filename="GzSceneManager" name="Scene Manager">
        <gz-gui>
          <property key="resizable" type="bool">false</property>
          <property key="width" type="double">5</property>
          <property key="height" type="double">5</property>
          <property key="state" type="string">floating</property>
          <property key="showTitleBar" type="bool">false</property>
        </gz-gui>
      </plugin>
      <plugin filename="InteractiveViewControl" name="Interactive view control">
        <gz-gui>
          <property key="resizable" type="bool">false</property>
          <property key="width" type="double">5</property>
          <property key="height" type="double">5</property>
          <property key="state" type="string">floating</property>
          <property key="showTitleBar" type="bool">false</property>
        </gz-gui>
      </plugin>
      <plugin filename="CameraTracking" name="Camera Tracking">
        <gz-gui>
          <property key="resizable" type="bool">false</property>
          <property key="width" type="double">5</property>
          <property key="height" type="double">5</property>
          <property key="state" type="string">floating</property>
          <property key="showTitleBar" type="bool">false</property>
        </gz-gui>
      </plugin>
      <plugin filename="MarkerManager" name="Marker manager">
        <gz-gui>
          <property key="resizable" type="bool">false</property>
          <property key="width" type="double">5</property>
          <property key="height" type="double">5</property>
          <property key="state" type="string">floating</property>
          <property key="showTitleBar" type="bool">false</property>
        </gz-gui>
      </plugin>
      <plugin filename="SelectEntities" name="Select Entities">
        <gz-gui>
          <anchors target="Select entities">
            <line own="right" target="right"/>
            <line own="top" target="top"/>
          </anchors>
          <property key="resizable" type="bool">false</property>
          <property key="width" type="double">5</property>
          <property key="height" type="double">5</property>
          <property key="state" type="string">floating</property>
          <property key="showTitleBar" type="bool">false</property>
        </gz-gui>
      </plugin>
      <plugin filename="VisualizationCapabilities" name="Visualization Capabilities">
        <gz-gui>
          <property key="resizable" type="bool">false</property>
          <property key="width" type="double">5</property>
          <property key="height" type="double">5</property>
          <property key="state" type="string">floating</property>
          <property key="showTitleBar" type="bool">false</property>
        </gz-gui>
      </plugin>

      <plugin filename="Spawn" name="Spawn Entities">
        <gz-gui>
          <anchors target="Select entities">
            <line own="right" target="right"/>
            <line own="top" target="top"/>
          </anchors>
          <property key="resizable" type="bool">false</property>
          <property key="width" type="double">5</property>
          <property key="height" type="double">5</property>
          <property key="state" type="string">floating</property>
          <property key="showTitleBar" type="bool">false</property>
        </gz-gui>
      </plugin>

      <!-- World control -->
      <plugin filename="WorldControl" name="World control">
        <gz-gui>
          <title>World control</title>
          <property type="bool" key="showTitleBar">false</property>
          <property type="bool" key="resizable">false</property>
          <property type="double" key="height">72</property>
          <property type="double" key="width">121</property>
          <property type="double" key="z">1</property>

          <property type="string" key="state">floating</property>
          <anchors target="3D View">
            <line own="left" target="left"/>
            <line own="bottom" target="bottom"/>
          </anchors>
        </gz-gui>

        <play_pause>true</play_pause>
        <step>true</step>
        <start_paused>true</start_paused>
        <use_event>true</use_event>

      </plugin>

      <!-- World statistics -->
      <plugin filename="WorldStats" name="World stats">
        <gz-gui>
          <title>World stats</title>
          <property type="bool" key="showTitleBar">false</property>
          <property type="bool" key="resizable">false</property>
          <property type="double" key="height">110</property>
          <property type="double" key="width">290</property>
          <property type="double" key="z">1</property>

          <property type="string" key="state">floating</property>
          <anchors target="3D View">
            <line own="right" target="right"/>
            <line own="bottom" target="bottom"/>
          </anchors>
        </gz-gui>

        <sim_time>true</sim_time>
        <real_time>true</real_time>
        <real_time_factor>true</real_time_factor>
        <iterations>true</iterations>
      </plugin>

      <!-- Insert simple shapes -->
      <plugin filename="Shapes" name="Shapes">
        <gz-gui>
          <property key="resizable" type="bool">false</property>
          <property key="x" type="double">0</property>
          <property key="y" type="double">0</property>
          <property key="width" type="double">250</property>
          <property key="height" type="double">50</property>
          <property key="state" type="string">floating</property>
          <property key="showTitleBar" type="bool">false</property>
          <property key="cardBackground" type="string">#666666</property>
        </gz-gui>
      </plugin>

      <!-- Insert lights -->
      <plugin filename="Lights" name="Lights">
        <gz-gui>
          <property key="resizable" type="bool">false</property>
          <property key="x" type="double">250</property>
          <property key="y" type="double">0</property>
          <property key="width" type="double">150</property>
          <property key="height" type="double">50</property>
          <property key="state" type="string">floating</property>
          <property key="showTitleBar" type="bool">false</property>
          <property key="cardBackground" type="string">#666666</property>
        </gz-gui>
      </plugin>

      <!-- Translate / rotate -->
      <plugin filename="TransformControl" name="Transform control">
        <gz-gui>
          <property key="resizable" type="bool">false</property>
          <property key="x" type="double">0</property>
          <property key="y" type="double">50</property>
          <property key="width" type="double">250</property>
          <property key="height" type="double">50</property>
          <property key="state" type="string">floating</property>
          <property key="showTitleBar" type="bool">false</property>
          <property key="cardBackground" type="string">#777777</property>
        </gz-gui>
      </plugin>

      <!-- Screenshot -->
      <plugin filename="Screenshot" name="Screenshot">
        <gz-gui>
          <property key="resizable" type="bool">false</property>
          <property key="x" type="double">250</property>
          <property key="y" type="double">50</property>
          <property key="width" type="double">50</property>
          <property key="height" type="double">50</property>
          <property key="state" type="string">floating</property>
          <property key="showTitleBar" type="bool">false</property>
          <property key="cardBackground" type="string">#777777</property>
        </gz-gui>
      </plugin>

      <!-- Video recorder -->
      <plugin filename="VideoRecorder" name="VideoRecorder">
        <gz-gui>
          <property key="resizable" type="bool">false</property>
          <property key="x" type="double">300</property>
          <property key="y" type="double">50</property>
          <property key="width" type="double">50</property>
          <property key="height" type="double">50</property>
          <property key="state" type="string">floating</property>
          <property key="showTitleBar" type="bool">false</property>
          <property key="cardBackground" type="string">#777777</property>
        </gz-gui>

        <record_video>
          <use_sim_time>true</use_sim_time>
          <lockstep>false</lockstep>
          <bitrate>4000000</bitrate>
        </record_video>
      </plugin>

      <!-- Inspector -->
      <plugin filename="ComponentInspector" name="Component inspector">
        <gz-gui>
          <property type="string" key="state">docked_collapsed</property>
        </gz-gui>
      </plugin>

      <!-- Entity tree -->
      <plugin filename="EntityTree" name="Entity tree">
        <gz-gui>
          <property type="string" key="state">docked_collapsed</property>
        </gz-gui>
      </plugin>

      <!-- View angle -->
      <plugin filename="ViewAngle" name="View angle">
        <gz-gui>
          <property type="string" key="state">docked_collapsed</property>
        </gz-gui>
      </plugin>

      <!-- KeyPublisher plugin-->
      <plugin filename="KeyPublisher" name="Key Publisher"/>

    </gui>

    <!-- 按Q键触发分离 -->
    <plugin filename="gz-sim-triggered-publisher-system"
            name="gz::sim::systems::TriggeredPublisher">
      <input type="ignition.msgs.Int32" topic="/keyboard/keypress">
        <match field="data">81</match>
      </input>
      <output type="ignition.msgs.Empty" topic="/model/anchor/detachable_joint/detach"/>
    </plugin>

    <!-- 高空锚点 -->
    <model name="anchor">
      <static>false</static>
      <pose>0 0 2.5 0 0 0</pose>
      <link name="anchor_link">
        <inertial>
          <mass>100.0</mass>
          <inertia>
            <ixx>16.67</ixx>
            <iyy>16.67</iyy>
            <izz>16.67</izz>
            <ixy>0</ixy>
            <ixz>0</ixz>
            <iyz>0</iyz>
          </inertia>
        </inertial>
        <visual name="visual">
          <geometry>
            <box>
              <size>1 1 1</size>
            </box>
          </geometry>
          <material>
            <ambient>1 0 0 0.5</ambient>
            <diffuse>1 0 0 0.5</diffuse>
            <specular>1 0 0 0.5</specular>
          </material>
        </visual>
        <collision name="collision">
          <geometry>
            <box>
              <size>1 1 1</size>
            </box>
          </geometry>
        </collision>
      </link>

      <!-- 添加四个支撑柱子 -->
      <!-- 西南角支撑柱 -->
      <link name="pillar_sw">
        <pose relative_to="anchor_link">-0.5 -0.5 -1.5 0 0 0</pose>
        <inertial>
          <mass>1.0</mass>
          <inertia>
            <ixx>0.33</ixx>
            <iyy>0.33</iyy>
            <izz>0.0033</izz>
            <ixy>0</ixy>
            <ixz>0</ixz>
            <iyz>0</iyz>
          </inertia>
        </inertial>
        <visual name="visual">
          <geometry>
            <cylinder>
              <radius>0.05</radius>
              <length>2.0</length>
            </cylinder>
          </geometry>
          <material>
            <ambient>0.8 0.8 0.8 1</ambient>
            <diffuse>0.8 0.8 0.8 1</diffuse>
            <specular>0.8 0.8 0.8 1</specular>
          </material>
        </visual>
        <collision name="collision">
          <geometry>
            <cylinder>
              <radius>0.05</radius>
              <length>2.0</length>
            </cylinder>
          </geometry>
        </collision>
      </link>

      <!-- 东南角支撑柱 -->
      <link name="pillar_se">
        <pose relative_to="anchor_link">0.5 -0.5 -1.5 0 0 0</pose>
        <inertial>
          <mass>1.0</mass>
          <inertia>
            <ixx>0.33</ixx>
            <iyy>0.33</iyy>
            <izz>0.0033</izz>
            <ixy>0</ixy>
            <ixz>0</ixz>
            <iyz>0</iyz>
          </inertia>
        </inertial>
        <visual name="visual">
          <geometry>
            <cylinder>
              <radius>0.05</radius>
              <length>2.0</length>
            </cylinder>
          </geometry>
          <material>
            <ambient>0.8 0.8 0.8 1</ambient>
            <diffuse>0.8 0.8 0.8 1</diffuse>
            <specular>0.8 0.8 0.8 1</specular>
          </material>
        </visual>
        <collision name="collision">
          <geometry>
            <cylinder>
              <radius>0.05</radius>
              <length>2.0</length>
            </cylinder>
          </geometry>
        </collision>
      </link>

      <!-- 西北角支撑柱 -->
      <link name="pillar_nw">
        <pose relative_to="anchor_link">-0.5 0.5 -1.5 0 0 0</pose>
        <inertial>
          <mass>1.0</mass>
          <inertia>
            <ixx>0.33</ixx>
            <iyy>0.33</iyy>
            <izz>0.0033</izz>
            <ixy>0</ixy>
            <ixz>0</ixz>
            <iyz>0</iyz>
          </inertia>
        </inertial>
        <visual name="visual">
          <geometry>
            <cylinder>
              <radius>0.05</radius>
              <length>2.0</length>
            </cylinder>
          </geometry>
          <material>
            <ambient>0.8 0.8 0.8 1</ambient>
            <diffuse>0.8 0.8 0.8 1</diffuse>
            <specular>0.8 0.8 0.8 1</specular>
          </material>
        </visual>
        <collision name="collision">
          <geometry>
            <cylinder>
              <radius>0.05</radius>
              <length>2.0</length>
            </cylinder>
          </geometry>
        </collision>
      </link>

      <!-- 东北角支撑柱 -->
      <link name="pillar_ne">
        <pose relative_to="anchor_link">0.5 0.5 -1.5 0 0 0</pose>
        <inertial>
          <mass>1.0</mass>
          <inertia>
            <ixx>0.33</ixx>
            <iyy>0.33</iyy>
            <izz>0.0033</izz>
            <ixy>0</ixy>
            <ixz>0</ixz>
            <iyz>0</iyz>
          </inertia>
        </inertial>
        <visual name="visual">
          <geometry>
            <cylinder>
              <radius>0.05</radius>
              <length>2.0</length>
            </cylinder>
          </geometry>
          <material>
            <ambient>0.8 0.8 0.8 1</ambient>
            <diffuse>0.8 0.8 0.8 1</diffuse>
            <specular>0.8 0.8 0.8 1</specular>
          </material>
        </visual>
        <collision name="collision">
          <geometry>
            <cylinder>
              <radius>0.05</radius>
              <length>2.0</length>
            </cylinder>
          </geometry>
        </collision>
      </link>

      <joint name="joint_anchor_sw" type="fixed">
        <parent>anchor_link</parent>
        <child>pillar_sw</child>
      </joint>

      <joint name="joint_anchor_se" type="fixed">
        <parent>anchor_link</parent>
        <child>pillar_se</child>
      </joint>

      <joint name="joint_anchor_nw" type="fixed">
        <parent>anchor_link</parent>
        <child>pillar_nw</child>
      </joint>

      <joint name="joint_anchor_ne" type="fixed">
        <parent>anchor_link</parent>
        <child>pillar_ne</child>
      </joint>

      <plugin filename="gz-sim-detachable-joint-system"
              name="gz::sim::systems::DetachableJoint">
        <parent_link>anchor_link</parent_link>
        <child_model>hector_v2</child_model>
        <child_link>base_link</child_link>
        <detach_topic>/model/anchor/detachable_joint/detach</detach_topic>
        <attach_topic>/model/anchor/detachable_joint/attach</attach_topic>
        <output_topic>/model/anchor/detachable_joint/state</output_topic>
        <initial_attached>true</initial_attached>
      </plugin>
    </model>


    <model name='hector_v2'>
      <pose relative_to='world'>0 0 0.55 0 0 0</pose>
      <link name='base_link'>
        <inertial>
          <pose>2.630194634402946e-06 2.20585656671927e-05 4.29598456952481e-05 0 0 0</pose>
          <mass>5.7030000000000012</mass>
          <inertia>
            <ixx>0.046763409339870249</ixx>
            <ixy>1.194330878485007e-06</ixy>
            <ixz>-2.4024355602314572e-05</ixz>
            <iyy>0.037036939435384893</iyy>
            <iyz>-9.3345956514115385e-06</iyz>
            <izz>0.02488541982557952</izz>
          </inertia>
        </inertial>
        <collision name='base_link_fixed_joint_lump__trunk_collision'>
          <pose>0 0 0 0 0 0</pose>
          <geometry>
            <box>
              <size>0.125 0.19 0.248</size>
            </box>
          </geometry>
        </collision>
        <collision name='base_link_fixed_joint_lump__head_link_collision_1'>
          <pose>0.07000000000000001 0.0458 0.3 3.141592653589793 1.224646799147353e-16 -1.570796326794897</pose>
          <geometry>
            <box>
              <size>0.001 0.001 0.001</size>
            </box>
          </geometry>
        </collision>
        <collision name='base_link_fixed_joint_lump__imu_link_collision_2'>
          <pose>0 0 0 0 0 0</pose>
          <geometry>
            <box>
              <size>0.001 0.001 0.001</size>
            </box>
          </geometry>
          <surface>
            <contact>
              <ode/>
            </contact>
            <friction>
              <ode/>
            </friction>
          </surface>
        </collision>
        <collision name='base_link_fixed_joint_lump__nuc_link_collision_3'>
          <pose>-0.055 0.08 -0.055 0 0 3.141592653589793</pose>
          <geometry>
            <box>
              <size>0.001 0.001 0.001</size>
            </box>
          </geometry>
        </collision>
        <visual name='base_link_visual'>
          <pose>0 0 0 0 0 0</pose>
          <geometry>
            <box>
              <size>0.001 0.001 0.001</size>
            </box>
          </geometry>
        </visual>
        <visual name='base_link_fixed_joint_lump__trunk_visual_1'>
          <pose>0 0 0 0 0 0</pose>
          <geometry>
            <mesh>
              <scale>1 1 1</scale>
              <uri>meshes/body.stl</uri>
            </mesh>
          </geometry>
          <material>
            <diffuse>0.125 0.125 0.125 0.55</diffuse>
            <ambient>0.125 0.125 0.125 0.55</ambient>
          </material>
        </visual>
        <visual name='base_link_fixed_joint_lump__head_link_visual_2'>
          <pose>0.07000000000000001 0.0458 0.3 3.141592653589793 1.224646799147353e-16 -1.570796326794897</pose>
          <geometry>
            <mesh>
              <scale>0.001 0.001 0.001</scale>
              <uri>meshes/Head.STL</uri>
            </mesh>
          </geometry>
          <material>
            <diffuse>0.125 0.125 0.125 0.55</diffuse>
            <ambient>0.125 0.125 0.125 0.55</ambient>
          </material>
        </visual>
        <visual name='base_link_fixed_joint_lump__imu_link_visual_3'>
          <pose>0 0 0 0 0 0</pose>
          <geometry>
            <box>
              <size>0.001 0.001 0.001</size>
            </box>
          </geometry>
          <material>
            <diffuse>0.125 0.125 0.125 0.55</diffuse>
            <ambient>0.125 0.125 0.125 0.55</ambient>
          </material>
        </visual>
        <visual name='base_link_fixed_joint_lump__nuc_link_visual_4'>
          <pose>-0.055 0.08 -0.055 0 0 3.141592653589793</pose>
          <geometry>
            <mesh>
              <scale>1 1 1</scale>
              <uri>meshes/NUC_backpack.STL</uri>
            </mesh>
          </geometry>
          <material>
            <diffuse>0.125 0.125 0.125 0.55</diffuse>
            <ambient>0.125 0.125 0.125 0.55</ambient>
          </material>
        </visual>
        <sensor name='imu_sensor' type='imu'>
          <always_on>true</always_on>
          <update_rate>1000</update_rate>
          <visualize>true</visualize>
          <topic>/imu</topic>
          <imu>
            <angular_velocity>
              <x>
                <noise type='gaussian'>
                  <mean>0</mean>
                  <stddev>0.00020000000000000001</stddev>
                  <bias_mean>7.5000000000000002e-06</bias_mean>
                  <bias_stddev>7.9999999999999996e-07</bias_stddev>
                </noise>
              </x>
              <y>
                <noise type='gaussian'>
                  <mean>0</mean>
                  <stddev>0.00020000000000000001</stddev>
                  <bias_mean>7.5000000000000002e-06</bias_mean>
                  <bias_stddev>7.9999999999999996e-07</bias_stddev>
                </noise>
              </y>
              <z>
                <noise type='gaussian'>
                  <mean>0</mean>
                  <stddev>0.00020000000000000001</stddev>
                  <bias_mean>7.5000000000000002e-06</bias_mean>
                  <bias_stddev>7.9999999999999996e-07</bias_stddev>
                </noise>
              </z>
            </angular_velocity>
            <linear_acceleration>
              <x>
                <noise type='gaussian'>
                  <mean>0</mean>
                  <stddev>0.017000000000000001</stddev>
                  <bias_mean>0.10000000000000001</bias_mean>
                  <bias_stddev>0.001</bias_stddev>
                </noise>
              </x>
              <y>
                <noise type='gaussian'>
                  <mean>0</mean>
                  <stddev>0.017000000000000001</stddev>
                  <bias_mean>0.10000000000000001</bias_mean>
                  <bias_stddev>0.001</bias_stddev>
                </noise>
              </y>
              <z>
                <noise type='gaussian'>
                  <mean>0</mean>
                  <stddev>0.017000000000000001</stddev>
                  <bias_mean>0.10000000000000001</bias_mean>
                  <bias_stddev>0.001</bias_stddev>
                </noise>
              </z>
            </linear_acceleration>
          </imu>
          <plugin name='ignition::gazebo::systems::Imu' filename='libignition-gazebo-imu-system.so'/>
          <pose>0 0 0 0 -0 0</pose>
        </sensor>
      </link>
      <joint name='L_hip_yaw_joint' type='revolute'>
        <sensor name="L_hip_yaw_joint_force_torque" type="force_torque">
          <always_on>true</always_on>
          <update_rate>30</update_rate>
          <visualize>true</visualize>
          <topic>L_hip_yaw_joint/force_torque</topic>
          <force_torque>
            <frame>child</frame>
            <measure_direction>child_to_parent</measure_direction>
          </force_torque>
        </sensor>
        <pose relative_to='base_link'>0 0.047 -0.1265 0 0 0</pose>
        <parent>base_link</parent>
        <child>L_hip_yaw_link</child>
        <axis>
          <xyz>0 0 1</xyz>
          <limit>
            <lower>-0.52359877559829882</lower>
            <upper>0.52359877559829882</upper>
             <effort>50</effort>
             
          </limit>
          <dynamics>
            <damping>0.10000000000000001</damping>
            <friction>0</friction>
            <spring_reference>0</spring_reference>
            <spring_stiffness>0</spring_stiffness>
          </dynamics>
        </axis>
        <physics>
          <ode>
            <limit>
              <cfm>0</cfm>
              <erp>0.20000000000000001</erp>
            </limit>
          </ode>
        </physics>

      </joint>
      <link name='L_hip_yaw_link'>
        <pose relative_to='L_hip_yaw_joint'>0 0 0 0 0 0</pose>
        <inertial>
          <pose>0.06518811899313502 0.01056818306636156 -0.05876998627002288 0 0 0</pose>
          <mass>0.874</mass>
          <inertia>
            <ixx>0.00083962526042654414</ixx>
            <ixy>-0.00015524278014096099</ixy>
            <ixz>0.00041089241044942743</ixz>
            <iyy>0.001276880976027457</iyy>
            <iyz>0.0001318430083221968</iyz>
            <izz>0.001199172187542334</izz>
          </inertia>
        </inertial>
        <collision name='L_hip_yaw_link_collision'>
          <pose>0.015 0 -0.002 0 0 0</pose>
          <geometry>
            <box>
              <size>0.0001 0.0001 0.0001</size>
            </box>
          </geometry>
        </collision>
        <collision name='L_hip_yaw_link_fixed_joint_lump__L_hip_yaw_trans_link_collision_1'>
          <pose>0.079 0.015 -0.07049999999999999 0 1.570796326794897 0</pose>
          <geometry>
            <cylinder>
              <length>0.040000000000000001</length>
              <radius>0.044999999999999998</radius>
            </cylinder>
          </geometry>
        </collision>
        <visual name='L_hip_yaw_link_visual'>
          <pose>0 0 0.02 0 0 0</pose>
          <geometry>
            <mesh>
              <scale>1 1 1</scale>
              <uri>meshes/L_hip_yaw.STL</uri>
            </mesh>
          </geometry>
          <material>
            <diffuse>0.25 0.25 0.25 1</diffuse>
            <ambient>0.25 0.25 0.25 1</ambient>
          </material>
        </visual>
      </link>
      <joint name='L_hip_roll_joint' type='revolute'>
        <sensor name="L_hip_roll_joint_force_torque" type="force_torque">
          <always_on>true</always_on>
          <update_rate>30</update_rate>
          <visualize>true</visualize>
          <topic>L_hip_roll_joint/force_torque</topic>
          <force_torque>
            <frame>child</frame>
            <measure_direction>child_to_parent</measure_direction>
          </force_torque>
        </sensor>
        <pose relative_to='L_hip_yaw_link'>0.0465 0.015 -0.07049999999999999 0 0 0</pose>
        <parent>L_hip_yaw_link</parent>
        <child>L_hip_roll_link</child>
        <axis>
          <xyz>1 0 0</xyz>
          <limit>
            <lower>-0.52359877559829882</lower>
            <upper>0.52359877559829882</upper>
             <effort>50</effort>
             
          </limit>
          <dynamics>
            <damping>0.10000000000000001</damping>
            <friction>0</friction>
            <spring_reference>0</spring_reference>
            <spring_stiffness>0</spring_stiffness>
          </dynamics>
        </axis>
      </joint>
      <link name='L_hip_roll_link'>
        <pose relative_to='L_hip_roll_joint'>0 0 0 0 0 0</pose>
        <inertial>
          <pose>-0.05658471812080537 -0.01439187248322148 0 0 0 0</pose>
          <mass>0.745</mass>
          <inertia>
            <ixx>0.0004917181040828859</ixx>
            <ixy>-1.058686153322143e-05</ixy>
            <ixz>0</ixz>
            <iyy>0.00073156397147080502</iyy>
            <iyz>6.2143879783576284e-20</iyz>
            <izz>0.00059356457555369106</izz>
          </inertia>
        </inertial>
        <collision name='L_hip_roll_link_collision'>
          <pose>-0.1 0 0 0 0 0</pose>
          <geometry>
            <box>
              <size>1e-05 1e-05 1e-05</size>
            </box>
          </geometry>
        </collision>
        <collision name='L_hip_roll_link_fixed_joint_lump__L_hip_roll_trans_link_collision_1'>
          <pose>-0.06 -0.015 0 -1.570796326794896 0 0</pose>
          <geometry>
            <cylinder>
              <length>0.040000000000000001</length>
              <radius>0.044999999999999998</radius>
            </cylinder>
          </geometry>
        </collision>
        <visual name='L_hip_roll_link_visual'>
          <pose>0 0 0 0 0 0</pose>
          <geometry>
            <mesh>
              <scale>1 1 1</scale>
              <uri>meshes/L_hip_roll.STL</uri>
            </mesh>
          </geometry>
          <material>
            <diffuse>1 1 0 1</diffuse>
            <ambient>1 1 0 1</ambient>
          </material>
        </visual>
      </link>
      <joint name='L_hip_pitch_joint' type='revolute'>
        <pose relative_to='L_hip_roll_link'>-0.06 0.018 0 0 0 0</pose>
        <parent>L_hip_roll_link</parent>
        <child>L_hip_pitch_link</child>
        <axis>
          <xyz>0 1 0</xyz>
          <limit>
            <lower>-3.1400000000000001</lower>
            <upper>3.1400000000000001</upper>
             <effort>50</effort>
             
          </limit>
          <dynamics>
            <spring_reference>0</spring_reference>
            <spring_stiffness>0</spring_stiffness>
          </dynamics>
        </axis>
      </joint>
      <link name='L_hip_pitch_link'>
        <pose relative_to='L_hip_pitch_joint'>0 0 0 0 0 0</pose>
        <inertial>
          <pose>-4.859629248197734e-05 0.0442364675592173 -0.05928275695159629 0 0 0</pose>
          <mass>1.9419999999999999</mass>
          <inertia>
            <ixx>0.0094485760881047372</ixx>
            <ixy>-2.2957860494335731e-06</ixy>
            <ixz>-2.0605848534500521e-06</ixz>
            <iyy>0.0096199078252887753</iyy>
            <iyz>-0.00090346150390731121</iyz>
            <izz>0.002157651836318949</izz>
          </inertia>
        </inertial>
        <collision name='L_hip_pitch_link_collision'>
          <pose>0 0.0175 -0.09 0 0 0</pose>
          <geometry>
            <box>
              <size>0.06 0.035 0.18</size>
            </box>
          </geometry>
        </collision>
        <collision name='L_hip_pitch_link_fixed_joint_lump__L_hip_pitch1_trans_link_collision_1'>
          <pose>0 0.0625 0 -1.570796326794896 0 0</pose>
          <geometry>
            <cylinder>
              <length>0.040000000000000001</length>
              <radius>0.044999999999999998</radius>
            </cylinder>
          </geometry>
        </collision>
        <collision name='L_hip_pitch_link_fixed_joint_lump__L_hip_pitch2_trans_link_collision_2'>
          <pose>0 0.05 -0.097 -1.570796326794896 0 0</pose>
          <geometry>
            <cylinder>
              <length>0.040000000000000001</length>
              <radius>0.044999999999999998</radius>
            </cylinder>
          </geometry>
        </collision>
        <visual name='L_hip_pitch_link_visual'>
          <pose>0 0 0 0 0 0</pose>
          <geometry>
            <mesh>
              <scale>1 1 1</scale>
              <uri>meshes/l_thigh.stl</uri>
            </mesh>
          </geometry>
          <material>
            <diffuse>0.25 0.25 0.25 1</diffuse>
            <ambient>0.25 0.25 0.25 1</ambient>
          </material>
        </visual>
      </link>
      <joint name='L_knee_joint' type='revolute'>
        <pose relative_to='L_hip_pitch_link'>0 0 -0.22 0 0 0</pose>
        <parent>L_hip_pitch_link</parent>
        <child>L_knee_link</child>
        <axis>
          <xyz>0 1 0</xyz>
          <limit>
            <lower>-3.1400000000000001</lower>
            <upper>3.1400000000000001</upper>
            <effort>67</effort>
             
          </limit>
          <dynamics>
            <spring_reference>0</spring_reference>
            <spring_stiffness>0</spring_stiffness>
          </dynamics>
        </axis>
      </joint>
      <link name='L_knee_link'>
        <pose relative_to='L_knee_joint'>0 0 0 0 0 0</pose>
        <inertial>
          <pose>0 0.020417 -0.1141 0 0 0</pose>
          <mass>0.30299999999999999</mass>
          <inertia>
            <ixx>0.0019109999999999999</ixx>
            <ixy>0</ixy>
            <ixz>0</ixz>
            <iyy>0.0019103799999999999</iyy>
            <iyz>0</iyz>
            <izz>6.8351999999999999e-05</izz>
          </inertia>
        </inertial>
        <collision name='L_knee_link_collision'>
          <pose>0 0.015 -0.11 0 0 0</pose>
          <geometry>
            <cylinder>
              <length>0.20000000000000001</length>
              <radius>0.02</radius>
            </cylinder>
          </geometry>
        </collision>
        <visual name='L_knee_link_visual'>
          <pose>0 0 0 0 0 0</pose>
          <geometry>
            <mesh>
              <scale>1 1 1</scale>
              <uri>meshes/calf.stl</uri>
            </mesh>
          </geometry>
          <material>
            <diffuse>0.25 0.25 0.25 1</diffuse>
            <ambient>0.25 0.25 0.25 1</ambient>
          </material>
        </visual>
      </link>
      <joint name='L_ankle_joint' type='revolute'>
        <pose relative_to='L_knee_link'>0 0 -0.22 0 0 0</pose>
        <parent>L_knee_link</parent>
        <child>L_ankle_link</child>
        <axis>
          <xyz>0 1 0</xyz>
          <limit>
            <lower>-1.3999999999999999</lower>
            <upper>1.3999999999999999</upper>
             <effort>50</effort>
             
          </limit>
          <dynamics>
            <spring_reference>0</spring_reference>
            <spring_stiffness>0</spring_stiffness>
          </dynamics>
        </axis>
      </joint>
      <link name='L_ankle_link'>
        <sensor name='L_ankle_link' type='contact'>
          <contact>
            <collision>L_ankle_link_contact</collision>
          </contact>
          <always_on>true</always_on>
          <update_rate>30</update_rate>
        </sensor>
        <pose relative_to='L_ankle_joint'>0 0 0 0 0 0</pose>
        <inertial>
          <pose>0.01056406352171882 0.01794967772069127 -0.01712868752919197 0 0 0</pose>
          <mass>0.21410000000000001</mass>
          <inertia>
            <ixx>5.7450544578958412e-05</ixx>
            <ixy>1.015328456170129e-07</ixy>
            <ixz>7.5827309849602889e-08</ixz>
            <iyy>0.00029091549929593179</iyy>
            <iyz>1.033186274395053e-07</iyz>
            <izz>0.00024960237560049892</izz>
          </inertia>
        </inertial>
        <collision name='L_ankle_link_contact'>
          <pose>0.01 0.0194 -0.02 0 0 0</pose>
          <geometry>
            <box>
              <size>0.15 0.02 0.04</size>
            </box>
          </geometry>
        </collision>
        <visual name='L_ankle_link_visual'>
          <pose>0 0 0 0 0 0</pose>
          <geometry>
            <mesh>
              <scale>1 1 1</scale>
              <uri>meshes/foot_L2.stl</uri>
            </mesh>
          </geometry>
          <material>
            <diffuse>0.25 0.25 0.25 1</diffuse>
            <ambient>0.25 0.25 0.25 1</ambient>
          </material>
        </visual>
        <visual name='L_ankle_link_fixed_joint_lump__L_leg_EE_link_visual_1'>
          <pose>0 0.0194 -0.04 0 0 0</pose>
          <geometry>
            <sphere>
              <radius>0.01</radius>
            </sphere>
          </geometry>
          <material>
            <diffuse>0.25 0.25 0.25 1</diffuse>
            <ambient>0.25 0.25 0.25 1</ambient>
          </material>
        </visual>

      </link>
      <joint name='L_shoulder_yaw_joint' type='revolute'>
        <pose relative_to='base_link'>0 0.047 0.1725 0 0 0</pose>
        <parent>base_link</parent>
        <child>L_shoulder_yaw_link</child>
        <axis>
          <xyz>0 0 1</xyz>
          <limit>
            <lower>-1.3999999999999999</lower>
            <upper>1.5708</upper>
            <effort>17</effort>
            <velocity>33</velocity>
          </limit>
          <dynamics>
            <damping>0.10000000000000001</damping>
            <friction>0</friction>
            <spring_reference>0</spring_reference>
            <spring_stiffness>0</spring_stiffness>
          </dynamics>
        </axis>
      </joint>
      <link name='L_shoulder_yaw_link'>
        <pose relative_to='L_shoulder_yaw_joint'>0 0 0 0 0 0</pose>
        <inertial>
          <pose>0.00071 0.02838 0.04835 0 0 1.570796</pose>
          <mass>0.43559999999999999</mass>
          <inertia>
            <ixx>0.00042999999999999999</ixx>
            <ixy>0</ixy>
            <ixz>0</ixz>
            <iyy>0.00035</iyy>
            <iyz>0</iyz>
            <izz>0.00027</izz>
          </inertia>
        </inertial>
        <collision name='L_shoulder_yaw_link_collision'>
          <pose>0 -0.021 0 1.570796326794896 0 0</pose>
          <geometry>
            <cylinder>
              <length>0.080000000000000002</length>
              <radius>0.041000000000000002</radius>
            </cylinder>
          </geometry>
        </collision>
        <visual name='L_shoulder_yaw_link_visual'>
          <pose>0 0 -0.062 0 0 0</pose>
          <geometry>
            <mesh>
              <scale>1 1 1</scale>
              <uri>meshes/hector_arm/ShoulderYaw_L.stl</uri>
            </mesh>
          </geometry>
          <material>
            <diffuse>0.25 0.25 0.25 1</diffuse>
            <ambient>0.25 0.25 0.25 1</ambient>
          </material>
        </visual>
      </link>
      <joint name='L_shoulder_pitch_joint' type='revolute'>
        <pose relative_to='L_shoulder_yaw_link'>0 0.045 -0.018 0 0 0</pose>
        <parent>L_shoulder_yaw_link</parent>
        <child>L_shoulder_pitch_link</child>
        <axis>
          <xyz>0 1 0</xyz>
          <limit>
            <lower>-3.1400000000000001</lower>
            <upper>1.5708</upper>
            <effort>17</effort>
            <velocity>33</velocity>
          </limit>
          <dynamics>
            <damping>0.10000000000000001</damping>
            <friction>0</friction>
            <spring_reference>0</spring_reference>
            <spring_stiffness>0</spring_stiffness>
          </dynamics>
        </axis>
      </joint>
      <link name='L_shoulder_pitch_link'>
        <pose relative_to='L_shoulder_pitch_joint'>0 0 0 0 0 0</pose>
        <inertial>
          <pose>-0.0294 0.04541 0.0008899999999999999 0 0 0</pose>
          <mass>0.432</mass>
          <inertia>
            <ixx>0.00042000000000000002</ixx>
            <ixy>-2.0000000000000002e-05</ixy>
            <ixz>0</ixz>
            <iyy>0.00027</iyy>
            <iyz>0</iyz>
            <izz>0.00033</izz>
          </inertia>
        </inertial>
        <collision name='L_shoulder_pitch_link_collision'>
          <pose>0 0 -0.125 0 1.570796326794897 0</pose>
          <geometry>
            <box>
              <size>0.25 0.034 0.043</size>
            </box>
          </geometry>
        </collision>
        <visual name='L_shoulder_pitch_link_visual'>
          <pose>0 0 0 0 0 0</pose>
          <geometry>
            <mesh>
              <scale>1 1 1</scale>
              <uri>meshes/hector_arm/ShoulderPitch_L.stl</uri>
            </mesh>
          </geometry>
          <material>
            <diffuse>1 1 0 1</diffuse>
            <ambient>1 1 0 1</ambient>
          </material>
        </visual>
      </link>
      <joint name='L_shoulder_roll_joint' type='revolute'>
        <pose relative_to='L_shoulder_pitch_link'>-0.0135 0.045 0 0 0 0</pose>
        <parent>L_shoulder_pitch_link</parent>
        <child>L_shoulder_roll_link</child>
        <axis>
          <xyz>1 0 0</xyz>
          <limit>
            <lower>-1.3999999999999999</lower>
            <upper>1.3999999999999999</upper>
            <effort>17</effort>
            <velocity>33</velocity>
          </limit>
          <dynamics>
            <damping>0.10000000000000001</damping>
            <friction>0</friction>
            <spring_reference>0</spring_reference>
            <spring_stiffness>0</spring_stiffness>
          </dynamics>
        </axis>
      </joint>
      <link name='L_shoulder_roll_link'>
        <pose relative_to='L_shoulder_roll_joint'>0 0 0 0 0 0</pose>
        <inertial>
          <pose>0.04492 0.01006 -0.03218 0 0 0</pose>
          <mass>0.66483999999999999</mass>
          <inertia>
            <ixx>0.0031800000000000001</ixx>
            <ixy>1.0000000000000001e-05</ixy>
            <ixz>0</ixz>
            <iyy>0.0032499999999999999</iyy>
            <iyz>0.00036999999999999999</iyz>
            <izz>0.00048999999999999998</izz>
          </inertia>
        </inertial>
        <collision name='L_shoulder_roll_link_collision'>
          <pose>0.04 0 -0.125 0 1.570796326794897 0</pose>
          <geometry>
            <box>
              <size>0.25 0.034 0.043</size>
            </box>
          </geometry>
        </collision>
        <visual name='L_shoulder_roll_link_visual'>
          <pose>0 0 0 0 0 0</pose>
          <geometry>
            <mesh>
              <scale>1 1 1</scale>
              <uri>meshes/hector_arm/UpperArmRoll_L.stl</uri>
            </mesh>
          </geometry>
          <material>
            <diffuse>0.25 0.25 0.25 1</diffuse>
            <ambient>0.25 0.25 0.25 1</ambient>
          </material>
        </visual>
      </link>
      <joint name='L_elbow_joint' type='revolute'>
        <pose relative_to='L_shoulder_roll_link'>0.04 0 -0.2 0 0 0</pose>
        <parent>L_shoulder_roll_link</parent>
        <child>L_elbow_link</child>
        <axis>
          <xyz>0 1 0</xyz>
          <limit>
            <lower>-2.7799999999999998</lower>
            <upper>2.6299999999999999</upper>
            <effort>24.09</effort>
            <velocity>23.289999999999999</velocity>
          </limit>
          <dynamics>
            <damping>0.10000000000000001</damping>
            <friction>0</friction>
            <spring_reference>0</spring_reference>
            <spring_stiffness>0</spring_stiffness>
          </dynamics>
        </axis>
      </joint>
      <link name='L_elbow_link'>
        <pose relative_to='L_elbow_joint'>0 0 0 0 0 0</pose>
        <inertial>
          <pose>0 7.994933502216595e-05 -0.1172724255858138 0 0 0</pose>
          <mass>0.15790000000000001</mass>
          <inertia>
            <ixx>0.0012907848195005951</ixx>
            <ixy>0</ixy>
            <ixz>0</ixz>
            <iyy>0.001300784818861</iyy>
            <iyz>-6.6182059531364658e-10</iyz>
            <izz>2.0100000639594681e-05</izz>
          </inertia>
        </inertial>
        <collision name='L_elbow_link_collision'>
          <pose>0 0 -0.125 0 1.570796326794897 0</pose>
          <geometry>
            <box>
              <size>0.25 0.016 0.016</size>
            </box>
          </geometry>
        </collision>
        <visual name='L_elbow_link_visual'>
          <pose>0 0 0 0 0 0</pose>
          <geometry>
            <mesh>
              <scale>1 1 1</scale>
              <uri>meshes/hector_arm/ForeArmPitch.stl</uri>
            </mesh>
          </geometry>
          <material>
            <diffuse>0.25 0.25 0.25 1</diffuse>
            <ambient>0.25 0.25 0.25 1</ambient>
          </material>
        </visual>
        <visual name='L_elbow_link_fixed_joint_lump__L_arm_EE_link_visual_1'>
          <pose>0 0 -0.2 0 0 0</pose>
          <geometry>
            <sphere>
              <radius>0.01</radius>
            </sphere>
          </geometry>
          <material>
            <diffuse>0.25 0.25 0.25 1</diffuse>
            <ambient>0.25 0.25 0.25 1</ambient>
          </material>
        </visual>
      </link>
      <joint name='R_hip_yaw_joint' type='revolute'>
        <pose relative_to='base_link'>0 -0.047 -0.1265 0 0 0</pose>
        <parent>base_link</parent>
        <child>R_hip_yaw_link</child>
        <axis>
          <xyz>0 0 1</xyz>
          <limit>
            <lower>-0.52359877559829882</lower>
            <upper>0.52359877559829882</upper>
             <effort>50</effort>
             
          </limit>
          <dynamics>
            <damping>0.10000000000000001</damping>
            <friction>0</friction>
            <spring_reference>0</spring_reference>
            <spring_stiffness>0</spring_stiffness>
          </dynamics>
        </axis>
      </joint>
      <link name='R_hip_yaw_link'>
        <pose relative_to='R_hip_yaw_joint'>0 0 0 0 0 0</pose>
        <inertial>
          <pose>0.06518811899313502 -0.01174302974828375 -0.05876998627002288 0 0 0</pose>
          <mass>0.874</mass>
          <inertia>
            <ixx>0.00081671575012906127</ixx>
            <ixy>0.0001140888994929061</ixy>
            <ixz>0.00041089241044942743</ixz>
            <iyy>0.001276880976027457</iyy>
            <iyz>-9.6892259412356837e-05</iyz>
            <izz>0.0011762626772448511</izz>
          </inertia>
        </inertial>
        <collision name='R_hip_yaw_link_collision'>
          <pose>0.015 0 -0.002 0 0 0</pose>
          <geometry>
            <box>
              <size>0.0001 0.0001 0.0001</size>
            </box>
          </geometry>
        </collision>
        <collision name='R_hip_yaw_link_fixed_joint_lump__R_hip_yaw_trans_link_collision_1'>
          <pose>0.079 -0.015 -0.07049999999999999 0 1.570796326794897 0</pose>
          <geometry>
            <cylinder>
              <length>0.040000000000000001</length>
              <radius>0.044999999999999998</radius>
            </cylinder>
          </geometry>
        </collision>
        <visual name='R_hip_yaw_link_visual'>
          <pose>0 0 0.02 0 0 0</pose>
          <geometry>
            <mesh>
              <scale>1 1 1</scale>
              <uri>meshes/R_hip_yaw.STL</uri>
            </mesh>
          </geometry>
          <material>
            <diffuse>0.25 0.25 0.25 1</diffuse>
            <ambient>0.25 0.25 0.25 1</ambient>
          </material>
        </visual>
      </link>
      <joint name='R_hip_roll_joint' type='revolute'>
        <pose relative_to='R_hip_yaw_link'>0.0465 -0.015 -0.07049999999999999 0 0 0</pose>
        <parent>R_hip_yaw_link</parent>
        <child>R_hip_roll_link</child>
        <axis>
          <xyz>1 0 0</xyz>
          <limit>
            <lower>-0.52359877559829882</lower>
            <upper>0.52359877559829882</upper>
             <effort>50</effort>
             
          </limit>
          <dynamics>
            <damping>0.10000000000000001</damping>
            <friction>0</friction>
            <spring_reference>0</spring_reference>
            <spring_stiffness>0</spring_stiffness>
          </dynamics>
        </axis>
      </joint>
      <link name='R_hip_roll_link'>
        <pose relative_to='R_hip_roll_joint'>0 0 0 0 0 0</pose>
        <inertial>
          <pose>-0.05658471812080537 0.01178262416107383 0 0 0 0</pose>
          <mass>0.745</mass>
          <inertia>
            <ixx>0.00054259844636476507</ixx>
            <ixy>5.6011135111073821e-05</ixy>
            <ixz>0</ixz>
            <iyy>0.00073156397147080502</iyy>
            <iyz>6.2143879783576284e-20</iyz>
            <izz>0.00064444491783557023</izz>
          </inertia>
        </inertial>
        <collision name='R_hip_roll_link_collision'>
          <pose>-0.1 0 0 0 0 0</pose>
          <geometry>
            <box>
              <size>1e-05 1e-05 1e-05</size>
            </box>
          </geometry>
        </collision>
        <collision name='R_hip_roll_link_fixed_joint_lump__R_hip_roll_trans_link_collision_1'>
          <pose>-0.06 0.015 0 -1.570796326794896 0 0</pose>
          <geometry>
            <cylinder>
              <length>0.040000000000000001</length>
              <radius>0.044999999999999998</radius>
            </cylinder>
          </geometry>
        </collision>
        <visual name='R_hip_roll_link_visual'>
          <pose>0 0 0 0 0 0</pose>
          <geometry>
            <mesh>
              <scale>1 1 1</scale>
              <uri>meshes/R_hip_roll.STL</uri>
            </mesh>
          </geometry>
          <material>
            <diffuse>1 1 0 1</diffuse>
            <ambient>1 1 0 1</ambient>
          </material>
        </visual>
      </link>
      <joint name='R_hip_pitch_joint' type='revolute'>
        <pose relative_to='R_hip_roll_link'>-0.06 -0.018 0 0 0 0</pose>
        <parent>R_hip_roll_link</parent>
        <child>R_hip_pitch_link</child>
        <axis>
          <xyz>0 1 0</xyz>
          <limit>
            <lower>-3.1400000000000001</lower>
            <upper>3.1400000000000001</upper>
             <effort>50</effort>
             
          </limit>
          <dynamics>
            <spring_reference>0</spring_reference>
            <spring_stiffness>0</spring_stiffness>
          </dynamics>
        </axis>
      </joint>
      <link name='R_hip_pitch_link'>
        <pose relative_to='R_hip_pitch_joint'>0 0 0 0 0 0</pose>
        <inertial>
          <pose>-4.859629248197734e-05 -0.0442364675592173 -0.05928275695159629 0 0 0</pose>
          <mass>1.9419999999999999</mass>
          <inertia>
            <ixx>0.0094485760881047372</ixx>
            <ixy>2.2957860494335731e-06</ixy>
            <ixz>-2.0605848534500521e-06</ixz>
            <iyy>0.0096199078252887753</iyy>
            <iyz>0.00090346150390731121</iyz>
            <izz>0.002157651836318949</izz>
          </inertia>
        </inertial>
        <collision name='R_hip_pitch_link_collision'>
          <pose>0 -0.0175 -0.09 0 0 0</pose>
          <geometry>
            <box>
              <size>0.06 0.035 0.18</size>
            </box>
          </geometry>
        </collision>
        <collision name='R_hip_pitch_link_fixed_joint_lump__R_hip_pitch1_trans_link_collision_1'>
          <pose>0 -0.0625 0 -1.570796326794896 0 0</pose>
          <geometry>
            <cylinder>
              <length>0.040000000000000001</length>
              <radius>0.044999999999999998</radius>
            </cylinder>
          </geometry>
        </collision>
        <collision name='R_hip_pitch_link_fixed_joint_lump__R_hip_pitch2_trans_link_collision_2'>
          <pose>0 -0.05 -0.097 -1.570796326794896 0 0</pose>
          <geometry>
            <cylinder>
              <length>0.040000000000000001</length>
              <radius>0.044999999999999998</radius>
            </cylinder>
          </geometry>
        </collision>
        <visual name='R_hip_pitch_link_visual'>
          <pose>0 0 0 0 0 0</pose>
          <geometry>
            <mesh>
              <scale>1 1 1</scale>
              <uri>meshes/r_thigh.stl</uri>
            </mesh>
          </geometry>
          <material>
            <diffuse>0.25 0.25 0.25 1</diffuse>
            <ambient>0.25 0.25 0.25 1</ambient>
          </material>
        </visual>
      </link>
      <joint name='R_knee_joint' type='revolute'>
        <pose relative_to='R_hip_pitch_link'>0 0 -0.22 0 0 0</pose>
        <parent>R_hip_pitch_link</parent>
        <child>R_knee_link</child>
        <axis>
          <xyz>0 1 0</xyz>
          <limit>
            <lower>-3.1400000000000001</lower>
            <upper>3.1400000000000001</upper>
            <effort>67</effort>
             
          </limit>
          <dynamics>
            <spring_reference>0</spring_reference>
            <spring_stiffness>0</spring_stiffness>
          </dynamics>
        </axis>
      </joint>
      <link name='R_knee_link'>
        <pose relative_to='R_knee_joint'>0 0 0 0 0 0</pose>
        <inertial>
          <pose>0 -0.020417 -0.1141 0 0 0</pose>
          <mass>0.30299999999999999</mass>
          <inertia>
            <ixx>0.0019109999999999999</ixx>
            <ixy>0</ixy>
            <ixz>0</ixz>
            <iyy>0.0019103799999999999</iyy>
            <iyz>0</iyz>
            <izz>6.8351999999999999e-05</izz>
          </inertia>
        </inertial>
        <collision name='R_knee_link_collision'>
          <pose>0 -0.015 -0.11 0 0 0</pose>
          <geometry>
            <cylinder>
              <length>0.20000000000000001</length>
              <radius>0.02</radius>
            </cylinder>
          </geometry>
        </collision>
        <visual name='R_knee_link_visual'>
          <pose>0 0 0 0 0 0</pose>
          <geometry>
            <mesh>
              <scale>1 1 1</scale>
              <uri>meshes/calf.stl</uri>
            </mesh>
          </geometry>
          <material>
            <diffuse>0.25 0.25 0.25 1</diffuse>
            <ambient>0.25 0.25 0.25 1</ambient>
          </material>
        </visual>
      </link>
      <joint name='R_ankle_joint' type='revolute'>
        <pose relative_to='R_knee_link'>0 0 -0.22 0 0 0</pose>
        <parent>R_knee_link</parent>
        <child>R_ankle_link</child>
        <axis>
          <xyz>0 1 0</xyz>
          <limit>
            <lower>-1.3999999999999999</lower>
            <upper>1.3999999999999999</upper>
             <effort>50</effort>
             
          </limit>
          <dynamics>
            <spring_reference>0</spring_reference>
            <spring_stiffness>0</spring_stiffness>
          </dynamics>
        </axis>
      </joint>
      <link name='R_ankle_link'>
        <sensor name='R_ankle_link' type='contact'>
          <contact>
            <collision>R_ankle_link_contact</collision>
          </contact>
          <always_on>true</always_on>
          <update_rate>30</update_rate>
        </sensor>
        <pose relative_to='R_ankle_joint'>0 0 0 0 0 0</pose>
        <inertial>
          <pose>0.01056406352171882 -0.01794967772069127 -0.01712868752919197 0 0 0</pose>
          <mass>0.21410000000000001</mass>
          <inertia>
            <ixx>5.7450544578958412e-05</ixx>
            <ixy>9.8467154382991936e-08</ixy>
            <ixz>7.5827309849602889e-08</ixz>
            <iyy>0.00029091549929593179</iyy>
            <iyz>9.6681372560485979e-08</iyz>
            <izz>0.00024960237560049892</izz>
          </inertia>
        </inertial>
        <collision name='R_ankle_link_contact'>
          <pose>0.01 -0.0194 -0.02 0 0 0</pose>
          <geometry>
            <box>
              <size>0.15 0.02 0.04</size>
            </box>
          </geometry>
        </collision>
        <visual name='R_ankle_link_visual'>
          <pose>0 0 0 0 0 0</pose>
          <geometry>
            <mesh>
              <scale>1 1 1</scale>
              <uri>meshes/foot_R2.stl</uri>
            </mesh>
          </geometry>
          <material>
            <diffuse>0.25 0.25 0.25 1</diffuse>
            <ambient>0.25 0.25 0.25 1</ambient>
          </material>
        </visual>
        <visual name='R_ankle_link_fixed_joint_lump__R_leg_EE_link_visual_1'>
          <pose>0 -0.0194 -0.04 0 0 0</pose>
          <geometry>
            <sphere>
              <radius>0.01</radius>
            </sphere>
          </geometry>
          <material>
            <diffuse>0.25 0.25 0.25 1</diffuse>
            <ambient>0.25 0.25 0.25 1</ambient>
          </material>
        </visual>


      </link>

      <joint name='R_shoulder_yaw_joint' type='revolute'>
        <pose relative_to='base_link'>0 -0.047 0.1725 0 0 0</pose>
        <parent>base_link</parent>
        <child>R_shoulder_yaw_link</child>
        <axis>
          <xyz>0 0 1</xyz>
          <limit>
            <lower>-1.5708</lower>
            <upper>1.3999999999999999</upper>
            <effort>17</effort>
            <velocity>33</velocity>
          </limit>
          <dynamics>
            <damping>0.10000000000000001</damping>
            <friction>0</friction>
            <spring_reference>0</spring_reference>
            <spring_stiffness>0</spring_stiffness>
          </dynamics>
        </axis>
      </joint>
      <link name='R_shoulder_yaw_link'>
        <pose relative_to='R_shoulder_yaw_joint'>0 0 0 0 0 0</pose>
        <inertial>
          <pose>0.00071 -0.02838 0.04835 0 0 1.570796</pose>
          <mass>0.43559999999999999</mass>
          <inertia>
            <ixx>0.00042999999999999999</ixx>
            <ixy>0</ixy>
            <ixz>0</ixz>
            <iyy>0.00035</iyy>
            <iyz>0</iyz>
            <izz>0.00027</izz>
          </inertia>
        </inertial>
        <collision name='R_shoulder_yaw_link_collision'>
          <pose>0 0.021 0 1.570796326794896 0 0</pose>
          <geometry>
            <cylinder>
              <length>0.080000000000000002</length>
              <radius>0.041000000000000002</radius>
            </cylinder>
          </geometry>
        </collision>
        <visual name='R_shoulder_yaw_link_visual'>
          <pose>0 0 -0.062 0 0 0</pose>
          <geometry>
            <mesh>
              <scale>1 1 1</scale>
              <uri>meshes/hector_arm/ShoulderYaw_R.stl</uri>
            </mesh>
          </geometry>
          <material>
            <diffuse>0.25 0.25 0.25 1</diffuse>
            <ambient>0.25 0.25 0.25 1</ambient>
          </material>
        </visual>
      </link>
      <joint name='R_shoulder_pitch_joint' type='revolute'>
        <pose relative_to='R_shoulder_yaw_link'>0 -0.045 -0.018 0 0 0</pose>
        <parent>R_shoulder_yaw_link</parent>
        <child>R_shoulder_pitch_link</child>
        <axis>
          <xyz>0 1 0</xyz>
          <limit>
            <lower>-3.1400000000000001</lower>
            <upper>1.5708</upper>
            <effort>17</effort>
            <velocity>33</velocity>
          </limit>
          <dynamics>
            <damping>0.10000000000000001</damping>
            <friction>0</friction>
            <spring_reference>0</spring_reference>
            <spring_stiffness>0</spring_stiffness>
          </dynamics>
        </axis>
      </joint>
      <link name='R_shoulder_pitch_link'>
        <pose relative_to='R_shoulder_pitch_joint'>0 0 0 0 0 0</pose>
        <inertial>
          <pose>-0.0294 -0.04541 0.0008899999999999999 0 0 0</pose>
          <mass>0.432</mass>
          <inertia>
            <ixx>0.00042000000000000002</ixx>
            <ixy>2.0000000000000002e-05</ixy>
            <ixz>0</ixz>
            <iyy>0.00027</iyy>
            <iyz>0</iyz>
            <izz>0.00033</izz>
          </inertia>
        </inertial>
        <collision name='R_shoulder_pitch_link_collision'>
          <pose>0 0 -0.125 0 1.570796326794897 0</pose>
          <geometry>
            <box>
              <size>0.25 0.034 0.043</size>
            </box>
          </geometry>
        </collision>
        <visual name='R_shoulder_pitch_link_visual'>
          <pose>0 0 0 0 0 0</pose>
          <geometry>
            <mesh>
              <scale>1 1 1</scale>
              <uri>meshes/hector_arm/ShoulderPitch_R.stl</uri>
            </mesh>
          </geometry>
          <material>
            <diffuse>1 1 0 1</diffuse>
            <ambient>1 1 0 1</ambient>
          </material>
        </visual>
      </link>
      <joint name='R_shoulder_roll_joint' type='revolute'>
        <pose relative_to='R_shoulder_pitch_link'>-0.0135 -0.045 0 0 0 0</pose>
        <parent>R_shoulder_pitch_link</parent>
        <child>R_shoulder_roll_link</child>
        <axis>
          <xyz>1 0 0</xyz>
          <limit>
            <lower>-1.3999999999999999</lower>
            <upper>1.3999999999999999</upper>
            <effort>17</effort>
            <velocity>33</velocity>
          </limit>
          <dynamics>
            <damping>0.10000000000000001</damping>
            <friction>0</friction>
            <spring_reference>0</spring_reference>
            <spring_stiffness>0</spring_stiffness>
          </dynamics>
        </axis>
      </joint>
      <link name='R_shoulder_roll_link'>
        <pose relative_to='R_shoulder_roll_joint'>0 0 0 0 0 0</pose>
        <inertial>
          <pose>0.04492 -0.01006 -0.03218 0 0 0</pose>
          <mass>0.66483999999999999</mass>
          <inertia>
            <ixx>0.0031800000000000001</ixx>
            <ixy>-1.0000000000000001e-05</ixy>
            <ixz>0</ixz>
            <iyy>0.0032499999999999999</iyy>
            <iyz>-0.00036999999999999999</iyz>
            <izz>0.00048999999999999998</izz>
          </inertia>
        </inertial>
        <collision name='R_shoulder_roll_link_collision'>
          <pose>0.04 0 -0.125 0 1.570796326794897 0</pose>
          <geometry>
            <box>
              <size>0.25 0.034 0.043</size>
            </box>
          </geometry>
        </collision>
        <visual name='R_shoulder_roll_link_visual'>
          <pose>0 0 0 0 0 0</pose>
          <geometry>
            <mesh>
              <scale>1 1 1</scale>
              <uri>meshes/hector_arm/UpperArmRoll_R.stl</uri>
            </mesh>
          </geometry>
          <material>
            <diffuse>0.25 0.25 0.25 1</diffuse>
            <ambient>0.25 0.25 0.25 1</ambient>
          </material>
        </visual>
      </link>
      <joint name='R_elbow_joint' type='revolute'>
        <pose relative_to='R_shoulder_roll_link'>0.04 0 -0.2 0 0 0</pose>
        <parent>R_shoulder_roll_link</parent>
        <child>R_elbow_link</child>
        <axis>
          <xyz>0 1 0</xyz>
          <limit>
            <lower>-2.7799999999999998</lower>
            <upper>2.6299999999999999</upper>
            <effort>24.09</effort>
            <velocity>23.289999999999999</velocity>
          </limit>
          <dynamics>
            <damping>0.10000000000000001</damping>
            <friction>0</friction>
            <spring_reference>0</spring_reference>
            <spring_stiffness>0</spring_stiffness>
          </dynamics>
        </axis>
      </joint>
      <link name='R_elbow_link'>
        <pose relative_to='R_elbow_joint'>0 0 0 0 0 0</pose>
        <inertial>
          <pose>0 7.994933502216595e-05 -0.1172724255858138 0 0 0</pose>
          <mass>0.15790000000000001</mass>
          <inertia>
            <ixx>0.0012907848195005951</ixx>
            <ixy>0</ixy>
            <ixz>0</ixz>
            <iyy>0.001300784818861</iyy>
            <iyz>-6.6182059531364658e-10</iyz>
            <izz>2.0100000639594681e-05</izz>
          </inertia>
        </inertial>
        <collision name='R_elbow_link_collision'>
          <pose>0 0 -0.125 0 1.570796326794897 0</pose>
          <geometry>
            <box>
              <size>0.25 0.016 0.016</size>
            </box>
          </geometry>
        </collision>
        <visual name='R_elbow_link_visual'>
          <pose>0 0 0 0 0 0</pose>
          <geometry>
            <mesh>
              <scale>1 1 1</scale>
              <uri>meshes/hector_arm/ForeArmPitch.stl</uri>
            </mesh>
          </geometry>
          <material>
            <diffuse>0.25 0.25 0.25 1</diffuse>
            <ambient>0.25 0.25 0.25 1</ambient>
          </material>
        </visual>
        <visual name='R_elbow_link_fixed_joint_lump__R_arm_EE_link_visual_1'>
          <pose>0 0 -0.2 0 0 0</pose>
          <geometry>
            <sphere>
              <radius>0.01</radius>
            </sphere>
          </geometry>
          <material>
            <diffuse>0.25 0.25 0.25 1</diffuse>
            <ambient>0.25 0.25 0.25 1</ambient>
          </material>
        </visual>
      </link>
      <plugin name='hector_gazebo_plugins::HectorGazeboFortressPlugin' filename='/home/cl/CLionProjects/hector_gazebo/install/hector_gazebo_fortress_plugin/lib/libhector_gazebo_fortress_plugin.so'>
        <joint_name>L_hip_yaw_joint</joint_name>
        <joint_name>L_hip_roll_joint</joint_name>
        <joint_name>L_hip_pitch_joint</joint_name>
        <joint_name>L_knee_joint</joint_name>
        <joint_name>L_ankle_joint</joint_name>
        <joint_name>R_hip_yaw_joint</joint_name>
        <joint_name>R_hip_roll_joint</joint_name>
        <joint_name>R_hip_pitch_joint</joint_name>
        <joint_name>R_knee_joint</joint_name>
        <joint_name>R_ankle_joint</joint_name>
        <joint_name>L_shoulder_yaw_joint</joint_name>
        <joint_name>L_shoulder_pitch_joint</joint_name>
        <joint_name>L_shoulder_roll_joint</joint_name>
        <joint_name>L_elbow_joint</joint_name>
        <joint_name>R_shoulder_yaw_joint</joint_name>
        <joint_name>R_shoulder_pitch_joint</joint_name>
        <joint_name>R_shoulder_roll_joint</joint_name>
        <joint_name>R_elbow_joint</joint_name>
        <base_link_name>base_link</base_link_name>
        <l_foot_link_name>L_ankle_link</l_foot_link_name>
        <r_foot_link_name>R_ankle_link</r_foot_link_name>
        <ign_imu_topic>/imu</ign_imu_topic>
        <ign_left_contact_topic>/world/default/model/hector_v2/link/L_ankle_link/sensor/L_ankle_link/contact</ign_left_contact_topic>
        <ign_right_contact_topic>/world/default/model/hector_v2/link/R_ankle_link/sensor/R_ankle_link/contact</ign_right_contact_topic>
      </plugin>
      <frame name='head' attached_to='trunk'>
        <pose>0.07 0.0458 0.3 3.14159 0 -1.5708</pose>
      </frame>
      <frame name='head_link' attached_to='head'/>
      <frame name='imu_joint' attached_to='trunk'>
        <pose>0 0 0 0 -0 0</pose>
      </frame>
      <frame name='imu_link' attached_to='imu_joint'/>
      <frame name='nuc_joint' attached_to='trunk'>
        <pose>-0.055 0.08 -0.055 0 -0 3.14159</pose>
      </frame>
      <frame name='nuc_link' attached_to='nuc_joint'/>
      <frame name='floating_base' attached_to='base_link'>
        <pose>0 0 0 0 -0 0</pose>
      </frame>
      <frame name='trunk' attached_to='floating_base'/>
      <frame name='L_hip_yaw_trans_joint' attached_to='L_hip_yaw_link'>
        <pose>0.079 0.015 -0.0705 0 -0 0</pose>
      </frame>
      <frame name='L_hip_yaw_trans_link' attached_to='L_hip_yaw_trans_joint'/>
      <frame name='L_hip_roll_trans_joint' attached_to='L_hip_roll_link'>
        <pose>-0.06 -0.015 0 0 -0 0</pose>
      </frame>
      <frame name='L_hip_roll_trans_link' attached_to='L_hip_roll_trans_joint'/>
      <frame name='L_hip_pitch1_trans_joint' attached_to='L_hip_pitch_link'>
        <pose>0 0.0625 0 0 -0 0</pose>
      </frame>
      <frame name='L_hip_pitch1_trans_link' attached_to='L_hip_pitch1_trans_joint'/>
      <frame name='L_hip_pitch2_trans_joint' attached_to='L_hip_pitch_link'>
        <pose>0 -0.0225 -0.097 0 -0 0</pose>
      </frame>
      <frame name='L_hip_pitch2_trans_link' attached_to='L_hip_pitch2_trans_joint'/>
      <frame name='L_leg_EE_joint' attached_to='L_ankle_link'>
        <pose>0 0.0194 -0.04 0 -0 0</pose>
      </frame>
      <frame name='L_leg_EE_link' attached_to='L_leg_EE_joint'/>
      <frame name='L_arm_EE_joint' attached_to='L_elbow_link'>
        <pose>0 0 -0.2 0 -0 0</pose>
      </frame>
      <frame name='L_arm_EE_link' attached_to='L_arm_EE_joint'/>
      <frame name='R_hip_yaw_trans_joint' attached_to='R_hip_yaw_link'>
        <pose>0.079 -0.015 -0.0705 0 -0 0</pose>
      </frame>
      <frame name='R_hip_yaw_trans_link' attached_to='R_hip_yaw_trans_joint'/>
      <frame name='R_hip_roll_trans_joint' attached_to='R_hip_roll_link'>
        <pose>-0.06 0.015 0 0 -0 0</pose>
      </frame>
      <frame name='R_hip_roll_trans_link' attached_to='R_hip_roll_trans_joint'/>
      <frame name='R_hip_pitch1_trans_joint' attached_to='R_hip_pitch_link'>
        <pose>0 -0.0625 0 0 -0 0</pose>
      </frame>
      <frame name='R_hip_pitch1_trans_link' attached_to='R_hip_pitch1_trans_joint'/>
      <frame name='R_hip_pitch2_trans_joint' attached_to='R_hip_pitch_link'>
        <pose>0 0.0225 -0.097 0 -0 0</pose>
      </frame>
      <frame name='R_hip_pitch2_trans_link' attached_to='R_hip_pitch2_trans_joint'/>
      <frame name='R_leg_EE_joint' attached_to='R_ankle_link'>
        <pose>0 -0.0194 -0.04 0 -0 0</pose>
      </frame>
      <frame name='R_leg_EE_link' attached_to='R_leg_EE_joint'/>
      <frame name='R_arm_EE_joint' attached_to='R_elbow_link'>
        <pose>0 0 -0.2 0 -0 0</pose>
      </frame>
      <frame name='R_arm_EE_link' attached_to='R_arm_EE_joint'/>
    </model>

  </world>
</sdf>