<!-- Credits: Lokesh Krishna -->
<!-- Date: June 6, 2024 -->

<!-- ***************   Hector XML Description *************** -->

<mujoco model="hector_v2">
	<compiler angle="radian"/>

  	<option timestep='0.001' o_solref='-100000 -1000' >
		<flag override='enable' />
	</option>

	<default>

		<default class="hector_v2">
					
			<default class="actuated_joint">
				<joint damping="0.1" armature="0.01" frictionloss="0.2" />
			</default>

			<default class="unactuated_joint">
				<joint damping="0.1" />
			</default>
		
			<default class="imu">
				<site type="box" size="0.01 0.008 0.0015" rgba="1 0 0 0" />
			</default>

			<default class="a1_actuator">
				<general biastype="affine" gainprm="30.0 0 0 0 0 0 0 0 0 0" biasprm="0 -30.0 -0.5 0 0 0 0 0 0 0" forcerange="-33.5 33.5" ctrlrange="-3.14 3.14" ctrllimited="true"/>
			</default>

			<default class="cybergear_actuator">
				<general biastype="affine" gainprm="5.0 0 0 0 0 0 0 0 0 0" biasprm="0 -5.0 -0.1 0 0 0 0 0 0 0" forcerange="-12.0 12.0" ctrlrange="-3.14 3.14" ctrllimited="true"/>
			</default>


		</default>
	</default>

	<visual>
		<headlight diffuse="0.6 0.6 0.6" ambient="0.3 0.3 0.3" specular="0 0 0" />
		<rgba haze="0.15 0.25 0.35 1" />

	    <global offheight="2160" offwidth="3840"/>
    	<quality offsamples="8"/>
	</visual>
	<asset>
		<texture type="skybox" builtin="gradient" rgb1="0.3 0.5 0.7" rgb2="0 0 0" width="512" height="3072" />
		<texture type="2d" name="groundplane" builtin="checker" mark="edge" rgb1="0.2 0.3 0.4" rgb2="0.1 0.2 0.3" markrgb="0.8 0.8 0.8" width="300" height="300" />
		<material name="groundplane" texture="groundplane" texuniform="true" texrepeat="5 5" reflectance="0.5" />
		<hfield name='terrain' nrow='500' ncol='500' size='10 10 2.0 0.1'/>
		<material name="black" rgba="0.2 0.2 0.2 1" />
		<material name="silver" rgba="0.75 0.75 0.75 1" />
		<material name="gray" rgba="0.5 0.5 0.5 1" />
		<material name="space_gray" rgba="0.39 0.45 0.50 1" />	
	</asset>

	<worldbody>
		<light name="spotlight0" mode="targetbodycom" target="trunk" pos="0 0 10" cutoff="60" />
		<light name="spotlight1" mode="targetbodycom" target="trunk" pos="0.5 0 10" cutoff="60" />
		<geom name='terrain' size="0 0 .125" conaffinity="15" condim="3"  pos="0 0 0" euler="0 0 0" material="groundplane" type='hfield' hfield='terrain'/>		

		<body name="trunk" pos="0 0 3.0" childclass="hector_v2">
			
			<freejoint name="root" />
			<site name="root" class="imu"/>
			
			<inertial pos="0.0 0.0 0.0" mass="5.89" diaginertia="0.0479073  0.03785748 0.02538835" />
			<geom size="0.06 0.103 0.120" type="box" material="black" rgba="0.2 0.2 0.2 0.5" />
			<geom size="0.035 0.0170" type="cylinder" material="black" pos="0.0 0.053 0.1227"/>
			<geom size="0.035 0.0170" type="cylinder" material="black" pos="0.0 -0.053 0.1227"/>


			<body name="l_hip" pos="0 0.047 -0.12">
				<inertial pos="0.0651881 0.0105682 -0.05877" quat="-0.0733308 0.865238 0.13671 0.476756" mass="0.874" diaginertia="0.00147219 0.00132639 0.000517101" />
				<joint name="l_hip_yaw_joint" pos="0 0 0" axis="0 0 1" limited="true" range="-0.78540 1.5708" class="actuated_joint" />
				<geom size="0.045 0.02" pos="0.079 0.015 -0.0705" quat="0.707107 0 0.707107 0" type="cylinder" material="black" />	
				<body name="l_hip2" pos="0.0465 0.015 -0.0705">
					<inertial pos="-0.0565847 -0.0143919 0" quat="0.490371 0.490371 0.509447 0.509447" mass="0.745" diaginertia="0.000770832 0.000552938 0.000493077" />
					<joint name="l_hip_roll_joint" pos="0 0 0" axis="1 0 0" limited="true" range="-0.78540 0.541052" class="actuated_joint" />				
					<geom size="0.045 0.02" pos="-0.06 -0.015 0" quat="0.707107 -0.707107 0 0" type="cylinder" material="black" />
					
					<body name="l_thigh" pos="-0.06 0.018 0" >
						<inertial pos="-4.85963e-05 0.0199702 -0.0592828" quat="0.98238 -0.186894 0.000253273 0.000716486" mass="1.942" diaginertia="0.0111784 0.0106783 0.00282909" />
						<joint name="l_hip_pitch_joint" pos="0 0 0" axis="0 1 0"  limited="true" range="-0.2894 2.0630" class="actuated_joint"/>
						<geom size="0.045 0.02" pos="0 0.0625 0" quat="0.707107 -0.707107 0 0" type="cylinder" material="black" />
						<geom size="0.045 0.02" pos="0 0.0625 -0.097" quat="0.707107 -0.707107 0 0" type="cylinder" material="black" />
						

						
						<geom size="0.0475 0.005 0.0475" pos="0  0  0.0" type="ellipsoid" material="silver" />
						<geom size="0.046 0.002 0.046" pos="0  0 -0.0475" type="box" material="silver" />
						<geom size="0.0475 0.005 0.11" pos="0 0 -0.11" type="ellipsoid" material="silver" />

						<geom size="0.0475 0.005 0.0475" pos="0  0.0425  0.0" type="ellipsoid" material="silver" />
						<geom size="0.046 0.002 0.046" pos="0 0.0425 -0.0475" type="box" material="silver" />
						<geom size="0.0475 0.005 0.11" pos="0  0.0425 -0.11" type="ellipsoid" material="silver" />

						<body name='l_toe_link_1' pos="0 0.0175 0" euler="0.0 1.9857 0.0">
							<joint name="l_toe_link_1_joint" pos="0 0 0" axis="0 1 0" limited="true" range="-1.74533 0.5235" solreflimit="4e-3 1" solimplimit=".95 .99 1e-3" class="actuated_joint"/>
							<geom size="0.0035 0.020"  pos="0.0 0.0 -0.020"  type="cylinder" material="silver" />
							<body name='l_toe_link_2' pos="0.0 0.0 -0.04" euler="0 1.1559316 0">
								<joint name="l_toe_link_2_joint" pos="0 0 0" axis="0 1 0" class="unactuated_joint" />
								<geom size="0.0035 0.11"  type="cylinder" pos="0.0 0.0 0.11" material="gray" />
								<body name='l_toe_link_3' pos="0.0 0.0 0.22"  >
									<joint name="l_toe_link_3_joint" pos="0 0 0" axis="0 1 0" class="unactuated_joint" />
									<geom size="0.0035 0.017"  type="cylinder" pos="-0.0175 0.0 0.0116" euler="0 -1.1559316 0" material="silver" />
									<geom size="0.0035 0.03227"  type="cylinder" pos="0.0 0.0 0.03227" material="silver" />
									<geom size="0.0035 0.0275" pos="-0.0126 0.0 0.0476"  euler="0 0.51906092 0" type="cylinder" material="silver" />
									<body name='l_toe_link_4' pos="0.0 0.00 0.072">
										<joint name="l_toe_link_4_joint" pos="0 0 0" axis="0 1 0" class="unactuated_joint"/>
										<geom size="0.0035 0.10"  pos="0.0 0.0 0.11" euler="0 0 0" type="cylinder"  material="gray" />
									</body> 
								
								</body>
							</body> 
						</body> 

						<body name="l_calf" pos="0 0 -0.22" >
							<inertial pos="0 0.020417 -0.1141" mass="0.303" diaginertia="0.001911 0.00191038 6.8352e-05" />
							<joint name="l_knee_joint" pos="0 0 0" axis="0 1 0"  limited="true" range="-2.37365 0" class="actuated_joint"/>
							<geom size="0.01 0.085" pos="0 0.02 -0.11" type="cylinder" material="silver" />
							

							<body name="l_toe" pos="0 0 -0.22" euler="0.0 -0.4814 0.0">
								<inertial pos="0.010569 0.017949 -0.017118" quat="0.5 0.5 0.5 0.5" mass="0.214" diaginertia="0.000290752 0.000249491 5.7298e-05" />
								<site name="l_toe_fs" class="imu"/>
								<joint name="l_ankle_joint" pos="0 0 0" axis="0 1 0" class="unactuated_joint"/>
								<!-- <geom size="0.07 0.012 0.0025" pos="0.010 0.0194 -0.035" type="box" rgba="0.8 0 0 0.2" /> -->
								<geom type="capsule" fromto="0.0  0.0194  0.0 0.0675  0.0194 -0.035" size="0.0035" material="silver" />
								<geom type="capsule" fromto="0.0  0.0194  0.0 -0.0475 0.0194 -0.035" size="0.0035" material="silver" />

								<!-- toe -->
								<geom size="0.0125 0.009 0.005" pos="0.0675  0.0194 -0.035" type="box" material="silver" /> 
								<!-- heel -->
								<geom size="0.0125 0.009 0.005" pos="-0.0475 0.0194 -0.035" type="box" material="silver" />
								<!-- feet -->
								<geom size="0.07 0.009 0.005" pos="0.01  0.0194 -0.035" type="box" material="silver" />




							</body>
						</body>
					</body>
				</body>
			</body>
			<body name="r_hip" pos="0 -0.047 -0.12">
				<inertial pos="0.0651881 -0.011743 -0.05877" quat="0.054396 0.871604 -0.102394 0.476301" mass="0.874" diaginertia="0.00144737 0.00130361 0.000518878" />
				<joint name="r_hip_yaw_joint" pos="0 0 0" axis="0 0 1"  limited="true" range="-1.5708 0.78540" class="actuated_joint"/>
				<geom size="0.045 0.02" pos="0.079 -0.015 -0.0705" quat="0.707107 0 0.707107 0" type="cylinder" material="black"/>
				<body name="r_hip2" pos="0.0465 -0.015 -0.0705">
					<inertial pos="-0.0565847 0.0117826 0" quat="0.554078 0.554078 0.439315 0.439315" mass="0.745" diaginertia="0.000783544 0.000603818 0.000531245" />
					<joint name="r_hip_roll_joint" pos="0 0 0" axis="1 0 0" limited="true" range="-0.541052 0.78540" class="actuated_joint"/>
					<geom size="0.045 0.02" pos="-0.06 0.015 0" quat="0.707107 -0.707107 0 0" type="cylinder" material="black"/>
					<body name="r_thigh" pos="-0.06 -0.018 0" >
						<inertial pos="-4.85963e-05 -0.0199702 -0.0592828" quat="0.98238 0.186894 0.000253273 -0.000716486" mass="1.942" diaginertia="0.0111784 0.0106783 0.00282909" />
						<joint name="r_hip_pitch_joint" pos="0 0 0" axis="0 1 0" limited="true" range="-0.2894 2.0630" class="actuated_joint"/>
						<geom size="0.045 0.02" pos="0 -0.0625 0" quat="0.707107 -0.707107 0 0" type="cylinder" material="black"/>
						<geom size="0.045 0.02" pos="0 -0.0625 -0.097" quat="0.707107 -0.707107 0 0" type="cylinder" material="black"/>
	



						<geom size="0.0475 0.005 0.0475" pos="0  0  0.0" type="ellipsoid" material="silver" />
						<geom size="0.046 0.002 0.046" pos="0  0 -0.0475" type="box" material="silver" />
						<geom size="0.0475 0.005 0.11" pos="0 0 -0.11" type="ellipsoid" material="silver" />

						<geom size="0.0475 0.005 0.0475" pos="0  -0.0425  0.0" type="ellipsoid" material="silver" />
						<geom size="0.046 0.002 0.046" pos="0 -0.0425 -0.0475" type="box" material="silver" />
						<geom size="0.0475 0.005 0.11" pos="0 -0.0425 -0.11" type="ellipsoid" material="silver" />

						<body name='r_toe_link_1' pos="0 -0.0175 0" euler="0.0 1.9857 0.0">
							<joint name="r_toe_link_1_joint" pos="0 0 0" axis="0 1 0" limited="true" range="-1.74533 0.5235" solreflimit="4e-3 1" solimplimit=".95 .99 1e-3" class="actuated_joint"/>
							<geom size="0.0035 0.020"  pos="0.0 0.0 -0.020"  type="cylinder" material="silver" />
							<body name='r_toe_link_2' pos="0.0 0.0 -0.04" euler="0 1.1559316 0">
								<joint name="r_toe_link_2_joint" pos="0 0 0" axis="0 1 0"  class="unactuated_joint"/>
								<geom size="0.0035 0.11"  type="cylinder" pos="0.0 0.0 0.11" material="gray" />
								<body name='r_toe_link_3' pos="0.0 0.0 0.22"  >
									<joint name="r_toe_link_3_joint" pos="0 0 0" axis="0 1 0"  class="unactuated_joint"/>
									<geom size="0.0035 0.017"  type="cylinder" pos="-0.0175 0.0 0.0116" euler="0 -1.1559316 0" material="silver" />
									<geom size="0.0035 0.03227"  type="cylinder" pos="0.0 0.0 0.03227" material="silver" />
									<geom size="0.0035 0.0275" pos="-0.0126 0.0 0.0476"  euler="0 0.51906092 0" type="cylinder" material="silver" />
									<body name='r_toe_link_4' pos="0.0 0.00 0.072">
										<joint name="r_toe_link_4_joint" pos="0 0 0" axis="0 1 0" class="unactuated_joint"/>
										<geom size="0.0035 0.10"  pos="0.0 0.0 0.11" euler="0 0 0" type="cylinder"  material="gray" />
									</body> 
								
								</body>
							</body> 
						</body> 

						<body name="r_calf" pos="0 0 -0.22" >
							<inertial pos="0 -0.020417 -0.1141" mass="0.303" diaginertia="0.001911 0.00191038 6.8352e-05" />
							<joint name="r_knee_joint" pos="0 0 0" axis="0 1 0" limited="true" range="-2.37365 0" class="actuated_joint"/>
							<geom size="0.01 0.085" pos="0 -0.02 -0.11" type="cylinder" material="silver" />						
							<body name="r_toe" pos="0 0 -0.22" euler="0.0 -0.4814 0.0">
								<inertial pos="0.010569 -0.017949 -0.017118" quat="0.5 0.5 0.5 0.5" mass="0.214" diaginertia="0.000290752 0.000249491 5.7298e-05" />
								<site name="r_toe_fs" class="imu"/>
								<joint name="r_ankle_joint" pos="0 0 0" axis="0 1 0" class="unactuated_joint"/>
								<!-- <geom size="0.07 0.012 0.0025" pos="0.010 -0.0194 -0.035" type="box" rgba="0.8 0 0 0.2" /> -->
								<geom type="capsule" fromto="0.0  -0.0194  0.0 0.0675  -0.0194 -0.035" size="0.0035" material="silver" />
								<geom type="capsule" fromto="0.0  -0.0194  0.0 -0.0475 -0.0194 -0.035" size="0.0035" material="silver" />
								<!-- toe -->
								<geom size="0.0125 0.009 0.005" pos="0.0675 -0.0194 -0.035" type="box" material="silver" />
								<!-- heel -->
								<geom size="0.0125 0.009 0.005" pos="-0.0475 -0.0194 -0.035" type="box" material="silver" />
								<!-- feet -->
								<geom size="0.07 0.009 0.005" pos="0.01  -0.0194 -0.035" type="box" material="silver" />

							</body>
						</body>
						

					</body>
				</body>
			</body>

			<body name="l_arm" pos="0.0 0.053 0.12">
				<joint name="l_shoulder_yaw_joint" pos="0 0 0" axis="0 0 1" limited="true" range="-1.4 1.5708" class="actuated_joint"/>
				<geom size="0.035 0.0170" type="cylinder" material="black" pos="0.0 0.045 0.0527" euler="1.5708 0.0 0.0"/>

				<body name="l_shoulder" pos="0.0 0.045 0.0527">
					<joint name="l_shoulder_pitch_joint" pos="0 0 0" axis="0 1 0" limited="true" range="-3.14 1.5708" class="actuated_joint"/>
					<geom size="0.035 0.0170" type="cylinder" material="black" pos="-0.014 0.053 0.0" euler="0.0 1.5708 0.0"/>
						
						<body name="l_upperearm" pos="-0.014 0.053 0.0">
							<joint name="l_shoulder_roll_joint" pos="0 0 0" axis="1 0 0" limited="true" range="-0.09 1.5708" class="actuated_joint"/>
                            <geom size="0.0125 0.065" fromto="0.0861 0 0 0.0651 0 -0.2" type="capsule" material="silver"/>
                            <geom size="0.0125 0.065" fromto="0.0441 0 0 0.0651 0 -0.2" type="capsule" material="silver"/>
                            <geom size="0.0125 0.065" fromto="0.0651 0 0 0.0651 0 -0.2" type="capsule" material="silver"/>


							<geom size="0.035 0.0170" type="cylinder" material="black" pos="0.0651 0.023  0.0" euler="1.5708 0.0 0.0"/>

							<body name="l_forearm" pos="0.0651 0.0 -0.2">
								<joint name="l_elbow_joint" pos="0 0 0" axis="0 1 0" limited="true" range="-2.79253 2.63" class="actuated_joint"/>
								<!-- <geom size="0.0125 0.006 0.07" type="box" material="space_gray" pos="0.0 0.0 -0.1" euler="0.0 0.0 0.0"/> -->
								<geom size="0.006 0.07" fromto="-0.0105 0 0 0 0 -0.2" type="capsule" material="silver"/>
								<geom size="0.006 0.07" fromto="0.0105 0 0 0 0 -0.2" type="capsule" material="silver"/>
								<body name="l_hand" pos="0.0 0.0 -0.2">
									<geom size="0.02" type="sphere" material="black" />
								</body>
							</body>
						</body>
				</body>

			</body> 

	
			<body name="r_arm" pos="0.0 -0.053 0.12">
				<joint name="r_shoulder_yaw_joint" pos="0 0 0" axis="0 0 1" limited="true" range="-1.5708 1.4" class="actuated_joint"/>
				<geom size="0.035 0.0170" type="cylinder" material="black" pos="0.0 -0.045 0.0527" euler="1.5708 0.0 0.0"/>

				<body name="r_shoulder" pos="0.0 -0.045 0.0527">
					<joint name="r_shoulder_pitch_joint" pos="0 0 0" axis="0 1 0" limited="true" range="-3.14 1.5708" class="actuated_joint"/>
					<geom size="0.035 0.0170" type="cylinder" material="black" pos="-0.014 -0.053 0.0" euler="0.0 1.5708 0.0"/>
						
						<body name="r_upperearm" pos="-0.014 -0.053 0.0">
							<joint name="r_shoulder_roll_joint" pos="0 0 0" axis="1 0 0" limited="true" range="-1.5708 0.09" class="actuated_joint"/>
							
                            <geom size="0.0125 0.065" fromto="0.0861 0 0 0.0651 0 -0.2" type="capsule" material="silver"/>
                            <geom size="0.0125 0.065" fromto="0.0441 0 0 0.0651 0 -0.2" type="capsule" material="silver"/>
                            <geom size="0.0125 0.065" fromto="0.0651 0 0 0.0651 0 -0.2" type="capsule" material="silver"/>

							<geom size="0.035 0.0170" type="cylinder" material="black" pos="0.0651 -0.023  0.0" euler="1.5708 0.0 0.0"/>

							<body name="r_forearm" pos="0.0651 0.0 -0.2">
								<joint name="r_elbow_joint" pos="0 0 0" axis="0 1 0" limited="true" range="-2.79253 2.63" class="actuated_joint"/>
								<!-- <geom size="0.0125 0.006 0.07" type="box" material="space_gray" pos="0.0 0.0 -0.1" euler="0.0 0.0 0.0"/> -->
								<geom size="0.006 0.07" fromto="-0.0105 0 0 0 0 -0.2" type="capsule" material="silver"/>
								<geom size="0.006 0.07" fromto="0.0105 0 0 0 0 -0.2" type="capsule" material="silver"/>
								<body name="r_hand" pos="0.0 0.0 -0.2">
									<geom size="0.02" type="sphere" material="black" />
								</body>
							</body>
						</body>
				</body>

			</body> 
	




		</body>

		<body name="v_trunk" pos="0 0 -0.5">
			<freejoint name="v_root" />
			<geom size="0.0625 0.095 0.124" type="box" rgba="0 0.5 0 0.5" contype="0" conaffinity="0" />
		</body> 

	</worldbody>

	<actuator>

		<general class="a1_actuator" name="l_hip_yaw" joint="l_hip_yaw_joint" ctrlrange="-0.15 0.27" />
		<general class="a1_actuator" name="l_hip_roll" joint="l_hip_roll_joint" ctrlrange="-0.15 0.55" />
		<general class="a1_actuator" name="l_hip_pitch" joint="l_hip_pitch_joint" ctrlrange="-0.3 2.1"/>
		<general class="a1_actuator" name="l_knee" joint="l_knee_joint"  ctrlrange="-4 0" gear="2.0"/>
		<general class="a1_actuator" name="l_ankle" joint="l_toe_link_1_joint" ctrlrange="-1.8 0.55"/> 

		<general class="a1_actuator" name="r_hip_yaw" joint="r_hip_yaw_joint" ctrlrange="-0.27 0.15" />
		<general class="a1_actuator" name="r_hip_roll" joint="r_hip_roll_joint" ctrlrange="-0.55 0.15"/>
		<general class="a1_actuator" name="r_hip_pitch" joint="r_hip_pitch_joint"  ctrlrange="-0.3 2.1"/>
		<general class="a1_actuator" name="r_knee" joint="r_knee_joint" ctrlrange="-4 0" gear="2.0"/>
		<general class="a1_actuator" name="r_ankle" joint="r_toe_link_1_joint" ctrlrange="-1.8 0.55"/> 

		<general class="cybergear_actuator" name="l_shoulder_yaw" joint="l_shoulder_yaw_joint" ctrlrange="-1.35 1.5708" />
		<general class="cybergear_actuator" name="l_shoulder_pitch" joint="l_shoulder_pitch_joint" ctrlrange="-3.14 1.5708" />
		<general class="cybergear_actuator" name="l_shoulder_roll" joint="l_shoulder_roll_joint" ctrlrange="-0.09 1.5708" />
		<general class="cybergear_actuator" name="l_elbow" joint="l_elbow_joint" ctrlrange="-2.79253 2.63" />

		<general class="cybergear_actuator" name="r_shoulder_yaw" joint="r_shoulder_yaw_joint" ctrlrange="-1.5708 1.35" />
		<general class="cybergear_actuator" name="r_shoulder_pitch" joint="r_shoulder_pitch_joint" ctrlrange="-3.14 1.5708" />
		<general class="cybergear_actuator" name="r_shoulder_roll" joint="r_shoulder_roll_joint" ctrlrange="-1.5708 0.09" />
		<general class="cybergear_actuator" name="r_elbow" joint="r_elbow_joint" ctrlrange="-2.79253 2.63" />

	</actuator>	

	<sensor>
		<accelerometer name="torso_acc"    site="root"/>
		<velocimeter name="torso_vel"        site="root"/>
		<gyro name="torso_gyr"              site="root"/>

		<accelerometer name="l_toe_acc"    site="l_toe_fs"/>
		<velocimeter name="l_toe_vel"        site="l_toe_fs"/>
		<gyro name="l_toe_gyr"              site="l_toe_fs"/>

		<accelerometer name="r_toe_acc"    site="r_toe_fs"/>
		<velocimeter name="r_toe_vel"        site="r_toe_fs"/>
		<gyro name="r_toe_gyr"              site="r_toe_fs"/>


		<!-- motor encoders -->
		<actuatorpos name="l_hip_yaw_pos" actuator="l_hip_yaw"/>
		<actuatorpos name="l_hip_roll_pos" actuator="l_hip_roll"/>
		<actuatorpos name="l_hip_pitch_pos" actuator="l_hip_pitch"/>
		<actuatorpos name="l_knee_pos" actuator="l_knee"/>
		<actuatorpos name="l_ankle_pos" actuator="l_ankle"/>

		<actuatorpos name="r_hip_yaw_pos" actuator="r_hip_yaw"/>
		<actuatorpos name="r_hip_roll_pos" actuator="r_hip_roll"/>
		<actuatorpos name="r_hip_pitch_pos" actuator="r_hip_pitch"/>
		<actuatorpos name="r_knee_pos" actuator="r_knee"/>
		<actuatorpos name="r_ankle_pos" actuator="r_ankle"/>

		<actuatorpos name="l_shoulder_yaw_pos" actuator="l_shoulder_yaw"/>
		<actuatorpos name="l_shoulder_pitch_pos" actuator="l_shoulder_pitch"/>
		<actuatorpos name="l_shoulder_roll_pos" actuator="l_shoulder_roll"/>
		<actuatorpos name="l_elbow_pos" actuator="l_elbow"/>

		<actuatorpos name="r_shoulder_yaw_pos" actuator="r_shoulder_yaw"/>
		<actuatorpos name="r_shoulder_pitch_pos" actuator="r_shoulder_pitch"/>
		<actuatorpos name="r_shoulder_roll_pos" actuator="r_shoulder_roll"/>
		<actuatorpos name="r_elbow_pos" actuator="r_elbow"/>

		<actuatorvel name="l_hip_yaw_vel" actuator="l_hip_yaw"/>
		<actuatorvel name="l_hip_roll_vel" actuator="l_hip_roll"/>
		<actuatorvel name="l_hip_pitch_vel" actuator="l_hip_pitch"/>
		<actuatorvel name="l_knee_vel" actuator="l_knee"/>
		<actuatorvel name="l_ankle_vel" actuator="l_ankle"/>

		<actuatorvel name="r_hip_yaw_vel" actuator="r_hip_yaw"/>
		<actuatorvel name="r_hip_roll_vel" actuator="r_hip_roll"/>
		<actuatorvel name="r_hip_pitch_vel" actuator="r_hip_pitch"/>
		<actuatorvel name="r_knee_vel" actuator="r_knee"/>
		<actuatorvel name="r_ankle_vel" actuator="r_ankle"/>

		<actuatorvel name="l_shoulder_yaw_vel" actuator="l_shoulder_yaw"/>
		<actuatorvel name="l_shoulder_pitch_vel" actuator="l_shoulder_pitch"/>
		<actuatorvel name="l_shoulder_roll_vel" actuator="l_shoulder_roll"/>
		<actuatorvel name="l_elbow_vel" actuator="l_elbow"/>

		<actuatorvel name="r_shoulder_yaw_vel" actuator="r_shoulder_yaw"/>
		<actuatorvel name="r_shoulder_pitch_vel" actuator="r_shoulder_pitch"/>
		<actuatorvel name="r_shoulder_roll_vel" actuator="r_shoulder_roll"/>
		<actuatorvel name="r_elbow_vel" actuator="r_elbow"/>
		<actuatorfrc name="l_hip_yaw_frc" actuator="l_hip_yaw"/>
		<actuatorfrc name="l_hip_roll_frc" actuator="l_hip_roll"/>
		<actuatorfrc name="l_hip_pitch_frc" actuator="l_hip_pitch"/>
		<actuatorfrc name="l_knee_frc" actuator="l_knee"/>
		<actuatorfrc name="l_ankle_frc" actuator="l_ankle"/>

		<actuatorfrc name="r_hip_yaw_frc" actuator="r_hip_yaw"/>
		<actuatorfrc name="r_hip_roll_frc" actuator="r_hip_roll"/>
		<actuatorfrc name="r_hip_pitch_frc" actuator="r_hip_pitch"/>
		<actuatorfrc name="r_knee_frc" actuator="r_knee"/>
		<actuatorfrc name="r_ankle_frc" actuator="r_ankle"/>

		<actuatorfrc name="l_shoulder_yaw_frc" actuator="l_shoulder_yaw"/>
		<actuatorfrc name="l_shoulder_pitch_frc" actuator="l_shoulder_pitch"/>
		<actuatorfrc name="l_shoulder_roll_frc" actuator="l_shoulder_roll"/>
		<actuatorfrc name="l_elbow_frc" actuator="l_elbow"/>

		<actuatorfrc name="r_shoulder_yaw_frc" actuator="r_shoulder_yaw"/>
		<actuatorfrc name="r_shoulder_pitch_frc" actuator="r_shoulder_pitch"/>
		<actuatorfrc name="r_shoulder_roll_frc" actuator="r_shoulder_roll"/>
		<actuatorfrc name="r_elbow_frc" actuator="r_elbow"/>

	</sensor>


	<equality>
		<weld name="world_root" active="true" body1="trunk" relpose="0 0 -0.7 1 0 0 0"/> 
		<connect name="l_toe_calf_connect1" body1="l_toe_link_3" body2="l_calf" anchor="-0.0349 0.0 0.0233" solref="0.002 1" />
		<connect name="l_toe_calf_connect2" body1="l_toe_link_4" body2="l_toe"  anchor="0.0 0.0 0.22" solref="0.002 1"/>
		<connect name="r_toe_calf_connect1" body1="r_toe_link_3" body2="r_calf" anchor="-0.0349 0.0 0.0233" solref="0.002 1"/>
		<connect name="r_toe_calf_connect2" body1="r_toe_link_4" body2="r_toe"  anchor="0.0 0.0 0.22" solref="0.002 1"/>
	</equality>

 <keyframe>
  	<key name="nominal" qpos='0.0 0.0 0.0 1 1.0196e-05 -0.000989896 -1.16096e-10 0.12939 0.0708572 1.00317 -0.213349 0.190542 -0.40584 -1.51937 -1.9943 1.41847 -0.12939 -0.0702581 1.00317 -0.213349 0.190542 -0.40584 -1.51937 -1.9943 1.41847 0.000286592 0.870285 -0.00363335 -2.39102 -0.000285856 0.870285 0.0036303 -2.39102 0 0 -534591 1 0 0 0' />
  </keyframe> 

</mujoco>